Workbook

Sheet Setup
A1: Nynaja Maternal Health VUI: Test Tally Sheet
A2: Keyword test, navigation command test and test-sentence test (WER/CER), English and Nyanja
A4: Test setup (fill in the yellow cells)
A5: Test date | C5: e.g. 17 Oct 2026
A6: Tester | C6: Your name
A7: Device (model, Android version) | C7: Real phone, so response times are meaningful
A8: ASR route tested | C8: e.g. Vosk (small model) / Google Speech-to-Text V2
A9: Test environment | C9: e.g. quiet room; describe the noise source and distance for noisy runs
A10: Speakers (S1, S2...) | C10: Number of speakers and a short description (e.g. S1 female, S2 male)
A12: How to use
A13: 1. Keyword Test: say each keyword to the app, then record the ASR transcript and the topic the app selected. Two rounds are set up (S1, S2).
A14: 2. Command Test: say each navigation word (yes, no, repeat, stop, back, menu, in both languages) and record the action triggered.
A15: 3. Sentence Test: read each test sentence aloud to the ASR and paste the transcript exactly as returned. If nothing is returned, type a dash (-).
A16: 4. If the ASR returns digits for a number word (e.g. 8 for 'eight'), change it to the word, because the reference sentences spell numbers out.
A17: 5. 'Correct?' fills itself. For every 'No', choose a failure type.
A18: 6. Run wer_cer.py on this file to get WER and CER, then type the results into section 7 of the Summary sheet.
A20: Legend
A21: Yellow cell, blue text | B21: Enter data here
A22: Grey cell | B22: Formula, do not edit
A23: Grey italic row | B23: Example row showing the format (not counted)
A25: Failure types
A26: ASR misheard | B26: Transcript differs from what was actually said.
A27: Keyword mismatch | B27: Transcript is right but the wrong topic was selected.
A28: Wrong action | B28: (Commands) Transcript is right but the wrong action was triggered.
A29: No match returned | B29: App said it did not understand / offered the menu instead of acting.
A30: Other | B30: Crash, timeout or anything else (describe in Notes).

Sheet Keywords
A1: Reference: topics, keywords and navigation commands
A2: Copied from nynaja_keywords_and_test_sentences.xlsx. The test sheets use these values and the topic names feed their dropdowns.
A4: ID | B4: Topic | C4: English keyword | D4: Nyanja keyword
A5: 1 | B5: Pregnancy | C5: pregnancy | D5: mimba
A6: 2 | B6: Clinic | C6: clinic | D6: kliniki
A7: 3 | B7: Food | C7: food | D7: chakudya
A8: 4 | B8: Danger | C8: danger | D8: ngozi
A9: 5 | B9: Bleeding | C9: bleeding | D9: magazi
A10: 6 | B10: Labour | C10: labour | D10: kubereka
A11: 7 | B11: Baby | C11: baby | D11: khanda
A12: 8 | B12: Breastfeeding | C12: breastfeeding | D12: kuyamwitsa
A13: 9 | B13: Vaccine | C13: vaccine | D13: katemera
A14: 10 | B14: Contraception | C14: contraception | D14: kulera
A15: 11 | B15: Malaria | C15: malaria | D15: malungo
A16: 12 | B16: Hygiene | C16: hygiene | D16: ukhondo
... A24: 20 | B24: Fever | C24: fever | D24: kutentha
A25: - | B25: No match
A27: Navigation commands
A28: Action | B28: English | C28: Nyanja
A29: Yes | B29: yes | C29: inde
A30: No | B30: no | C30: ayi
A31: Repeat | B31: repeat | C31: bwerezani
A32: Stop | B32: stop | C32: imani
A33: Back | B33: back | C33: bwerera
A34: Menu | B34: menu | C34: menyu

Sheet Keyword Test
A1: Keyword Test: say the keyword, record what the app did
A2: Grey columns are fixed. Fill the yellow cells. Row 4 is an example and is not counted.
A3: Trial | B3: Speaker | C3: Condition | D3: Language | E3: Topic ID | F3: Expected topic | G3: Keyword to say | H3: ASR transcript | I3: Topic selected | J3: Correct? | K3: Failure type | L3: Response time (s) | M3: Correct audio played? | N3: Notes
A4: EX | B4: S1 | C4: Quiet | D4: English | E4: 1 | F4: Pregnancy | G4: pregnancy | H4: pregnancy | I4: Pregnancy | J4: =IF(I4="","",IF(TRIM(F4)=TRIM(I4),"Yes","No")) -> Yes | K4: None | L4: 1.8 | M4: Yes | N4: Example row, ignore
A5: K001 | B5: S1 | C5: Quiet | D5: English | E5: 1 | F5: Pregnancy | G5: pregnancy | H5: pregnancy | I5: Pregnancy | J5: =IF(I5="","",IF(TRIM(F5)=TRIM(I5),"Yes","No")) -> Yes | K5: None | L5: 2.1 | M5: Yes
A6: K002 | B6: S1 | C6: Quiet | D6: English | E6: 2 | F6: Clinic | G6: clinic | H6: clinic | I6: clinic | J6: =IF(I6="","",IF(TRIM(F6)=TRIM(I6),"Yes","No")) -> Yes | L6: 4.17
A7: K003 | B7: S1 | C7: Quiet | D7: English | E7: 3 | F7: Food | G7: food | H7: food | I7: food | J7: =IF(I7="","",IF(TRIM(F7)=TRIM(I7),"Yes","No")) -> Yes | L7: 4.8
A8: K004 | B8: S1 | C8: Quiet | D8: English | E8: 4 | F8: Danger | G8: danger | H8: danger | I8: danger | J8: =IF(I8="","",IF(TRIM(F8)=TRIM(I8),"Yes","No")) -> Yes | L8: 3.55
A9: K005 | B9: S1 | C9: Quiet | D9: English | E9: 5 | F9: Bleeding | G9: bleeding | H9: bleeding | I9: bleeding | J9: =IF(I9="","",IF(TRIM(F9)=TRIM(I9),"Yes","No")) -> Yes | L9: 4.4
A10: K006 | B10: S1 | C10: Quiet | D10: English | E10: 6 | F10: Labour | G10: labour | H10: labour | I10: No match | J10: =IF(I10="","",IF(TRIM(F10)=TRIM(I10),"Yes","No")) -> No | K10: No match returned | L10: 4.3 | M10: no
A11: K007 | B11: S1 | C11: Quiet | D11: English | E11: 7 | F11: Baby | G11: baby | H11: baby | I11: baby | J11: =IF(I11="","",IF(TRIM(F11)=TRIM(I11),"Yes","No")) -> Yes | L11: 5.3
A12: K008 | B12: S1 | C12: Quiet | D12: English | E12: 8 | F12: Breastfeeding | G12: breastfeeding | H12: breastfeeding | I12: Breastfeeding | J12: =IF(I12="","",IF(TRIM(F12)=TRIM(I12),"Yes","No")) -> Yes | L12: 4.2
A13: K009 | B13: S1 | C13: Quiet | D13: English | E13: 9 | F13: Vaccine | G13: vaccine | H13: vaccine | I13: Vaccine | J13: =IF(I13="","",IF(TRIM(F13)=TRIM(I13),"Yes","No")) -> Yes | L13: 4.4
A14: K010 | B14: S1 | C14: Quiet | D14: English | E14: 10 | F14: Contraception | G14: contraception | H14: contraception | I14: Contraception | J14: =IF(I14="","",IF(TRIM(F14)=TRIM(I14),"Yes","No")) -> Yes | L14: 3.4
A15: K011 | B15: S1 | C15: Quiet | D15: English | E15: 11 | F15: Malaria | G15: malaria | H15: malaria | I15: Malaria | J15: =IF(I15="","",IF(TRIM(F15)=TRIM(I15),"Yes","No")) -> Yes | L15: 3.6
A16: K012 | B16: S1 | C16: Quiet | D16: English | E16: 12 | F16: Hygiene | G16: hygiene | H16: hygiene | I16: Hygiene | J16: =IF(I16="","",IF(TRIM(F16)=TRIM(I16),"Yes","No")) -> Yes | L16: 3.7
A17: K013 | B17: S1 | C17: Quiet | D17: English | E17: 13 | F17: Water | G17: water | H17: water | I17: Water | J17: =IF(I17="","",IF(TRIM(F17)=TRIM(I17),"Yes","No")) -> Yes | L17: 4.5
A18: K014 | B18: S1 | C18: Quiet | D18: English | E18: 14 | F18: Rest | G18: rest | H18: rest | I18: Rest | J18: =IF(I18="","",IF(TRIM(F18)=TRIM(I18),"Yes","No")) -> Yes | L18: 6.2 | N18: Failure to recognize on the repeat test.
A19: K015 | B19: S1 | C19: Quiet | D19: English | E19: 15 | F19: Medicine | G19: medicine | H19: medicine | I19: Medicine | J19: =IF(I19="","",IF(TRIM(F19)=TRIM(I19),"Yes","No")) -> Yes | L19: 3.4
A20: K016 | B20: S1 | C20: Quiet | D20: English | E20: 16 | F20: Pills | G20: pills | H20: pills | I20: Pills | J20: =IF(I20="","",IF(TRIM(F20)=TRIM(I20),"Yes","No")) -> Yes | L20: 3.1
A21: K017 | B21: S1 | C21: Quiet | D21: English | E21: 17 | F21: Postnatal | G21: postnatal | H21: postnatal | I21: No match | J21: =IF(I21="","",IF(TRIM(F21)=TRIM(I21),"Yes","No")) -> No | K21: No match returned | L21: 5.3 | M21: no
A22: K018 | B22: S1 | C22: Quiet | D22: English | E22: 18 | F22: Child | G22: child | H22: child | I22: Child | J22: =IF(I22="","",IF(TRIM(F22)=TRIM(I22),"Yes","No")) -> Yes | L22: 4.5
A23: K019 | B23: S1 | C23: Quiet | D23: English | E23: 19 | F23: Help | G23: help | H23: help | I23: Help | J23: =IF(I23="","",IF(TRIM(F23)=TRIM(I23),"Yes","No")) -> Yes | L23: 5.4
A24: K020 | B24: S1 | C24: Quiet | D24: English | E24: 20 | F24: Fever | G24: fever | H24: fever | I24: Fever | J24: =IF(I24="","",IF(TRIM(F24)=TRIM(I24),"Yes","No")) -> Yes | L24: 5
A25: K021 | B25: S1 | C25: Quiet | D25: Nyanja | E25: 1 | F25: Pregnancy | G25: mimba | J25: =IF(I25="","",IF(TRIM(F25)=TRIM(I25),"Yes","No"))
A26: K022 | B26: S1 | C26: Quiet | D26: Nyanja | E26: 2 | F26: Clinic | G26: kliniki | J26: =IF(I26="","",IF(TRIM(F26)=TRIM(I26),"Yes","No"))
A27: K023 | B27: S1 | C27: Quiet | D27: Nyanja | E27: 3 | F27: Food | G27: chakudya | J27: =IF(I27="","",IF(TRIM(F27)=TRIM(I27),"Yes","No"))
A28: K024 | B28: S1 | C28: Quiet | D28: Nyanja | E28: 4 | F28: Danger | G28: ngozi | J28: =IF(I28="","",IF(TRIM(F28)=TRIM(I28),"Yes","No"))
A29: K025 | B29: S1 | C29: Quiet | D29: Nyanja | E29: 5 | F29: Bleeding | G29: magazi | J29: =IF(I29="","",IF(TRIM(F29)=TRIM(I29),"Yes","No"))
A30: K026 | B30: S1 | C30: Quiet | D30: Nyanja | E30: 6 | F30: Labour | G30: kubereka | J30: =IF(I30="","",IF(TRIM(F30)=TRIM(I30),"Yes","No"))
A31: K027 | B31: S1 | C31: Quiet | D31: Nyanja | E31: 7 | F31: Baby | G31: khanda | J31: =IF(I31="","",IF(TRIM(F31)=TRIM(I31),"Yes","No"))
A32: K028 | B32: S1 | C32: Quiet | D32: Nyanja | E32: 8 | F32: Breastfeeding | G32: kuyamwitsa | J32: =IF(I32="","",IF(TRIM(F32)=TRIM(I32),"Yes","No"))
A33: K029 | B33: S1 | C33: Quiet | D33: Nyanja | E33: 9 | F33: Vaccine | G33: katemera | J33: =IF(I33="","",IF(TRIM(F33)=TRIM(I33),"Yes","No"))
A34: K030 | B34: S1 | C34: Quiet | D34: Nyanja | E34: 10 | F34: Contraception | G34: kulera | J34: =IF(I34="","",IF(TRIM(F34)=TRIM(I34),"Yes","No"))
A35: K031 | B35: S1 | C35: Quiet | D35: Nyanja | E35: 11 | F35: Malaria | G35: malungo | J35: =IF(I35="","",IF(TRIM(F35)=TRIM(I35),"Yes","No"))
A36: K032 | B36: S1 | C36: Quiet | D36: Nyanja | E36: 12 | F36: Hygiene | G36: ukhondo | J36: =IF(I36="","",IF(TRIM(F36)=TRIM(I36),"Yes","No"))
... A44: K040 | B44: S1 | C44: Quiet | D44: Nyanja | E44: 20 | F44: Fever | G44: kutentha | J44: =IF(I44="","",IF(TRIM(F44)=TRIM(I44),"Yes","No"))
A45: K041 | B45: S2 | C45: Quiet | D45: English | E45: 1 | F45: Pregnancy | G45: pregnancy | H45: pregnancy | I45: Pregnancy | J45: Yes | L45: 4.4
A46: K042 | B46: S2 | C46: Quiet | D46: English | E46: 2 | F46: Clinic | G46: clinic | H46: clinic | I46: Clinic | J46: Yes | L46: 4.5
A47: K043 | B47: S2 | C47: Quiet | D47: English | E47: 3 | F47: Food | G47: food | H47: food | I47: Food | J47: Yes | L47: 5.9
...

Sheet Command Test
A1: Command Test: navigation words
A2: Short words such as 'no' and 'ayi' are the easiest to misrecognise, so note any confusions. Row 4 is an example.
A3: Trial | B3: Speaker | C3: Language | D3: Expected action | E3: Word to say | F3: ASR transcript | G3: Action triggered | H3: Correct? | I3: Failure type | J3: Notes
A4: EX | B4: S1 | C4: English | D4: Repeat | E4: repeat | F4: repeat | G4: Repeat | H4: =IF(G4="","",IF(TRIM(D4)=TRIM(G4),"Yes","No")) -> Yes | I4: None | J4: Example row, ignore
A5: C001 | B5: S1 | C5: English | D5: Yes | E5: yes | H5: =IF(G5="","",IF(TRIM(D5)=TRIM(G5),"Yes","No"))
A6: C002 | B6: S1 | C6: English | D6: No | E6: no | H6: =IF(G6="","",IF(TRIM(D6)=TRIM(G6),"Yes","No"))
A7: C003 | B7: S1 | C7: English | D7: Repeat | E7: repeat | H7: =IF(G7="","",IF(TRIM(D7)=TRIM(G7),"Yes","No"))
A8: C004 | B8: S1 | C8: English | D8: Stop | E8: stop | H8: =IF(G8="","",IF(TRIM(D8)=TRIM(G8),"Yes","No"))
A9: C005 | B9: S1 | C9: English | D9: Back | E9: back | H9: =IF(G9="","",IF(TRIM(D9)=TRIM(G9),"Yes","No"))
A10: C006 | B10: S1 | C10: English | D10: Menu | E10: menu | H10: =IF(G10="","",IF(TRIM(D10)=TRIM(G10),"Yes","No"))
A11: C007 | B11: S1 | C11: Nyanja | D11: Yes | E11: inde | H11: =IF(G11="","",IF(TRIM(D11)=TRIM(G11),"Yes","No"))
A12: C008 | B12: S1 | C12: Nyanja | D12: No | E12: ayi | H12: =IF(G12="","",IF(TRIM(D12)=TRIM(G12),"Yes","No"))
A13: C009 | B13: S1 | C13: Nyanja | D13: Repeat | E13: bwerezani | H13: =IF(G13="","",IF(TRIM(D13)=TRIM(G13),"Yes","No"))
A14: C010 | B14: S1 | C14: Nyanja | D14: Stop | E14: imani | H14: =IF(G14="","",IF(TRIM(D14)=TRIM(G14),"Yes","No"))
A15: C011 | B15: S1 | C15: Nyanja | D15: Back | E15: bwerera | H15: =IF(G15="","",IF(TRIM(D15)=TRIM(G15),"Yes","No"))
A16: C012 | B16: S1 | C16: Nyanja | D16: Menu | E16: menyu | H16: =IF(G16="","",IF(TRIM(D16)=TRIM(G16),"Yes","No"))
... A28: C024 | B28: S2 | C28: Nyanja | D28: Menu | E28: menyu | H28: =IF(G28="","",IF(TRIM(D28)=TRIM(G28),"Yes","No"))

Sheet Sentence Test
A1: Sentence Test: read each sentence aloud, paste the ASR transcript
A2: WER and CER are computed by wer_cer.py from this sheet. Type a dash (-) if the ASR returns nothing. Row 4 is an example.
A3: Trial | B3: Speaker | C3: Language | D3: Topic ID | E3: Topic | F3: Reference sentence | G3: ASR transcript | H3: Notes
A4: EX | B4: S1 | C4: English | D4: 2 | E4: Clinic | F4: Visit the clinic at least eight times during your pregnancy. | G4: visit the clinic at least 8 times during your pregnancy | H4: Example row (digit instead of word, fix it)
A5: S001 | B5: S1 | C5: English | D5: 1 | E5: Pregnancy | F5: Go to the clinic as soon as you know you are pregnant. Eat well and rest often.
A6: S002 | B6: S1 | C6: English | D6: 2 | E6: Clinic | F6: Visit the clinic at least eight times during your pregnancy.
A7: S003 | B7: S1 | C7: English | D7: 3 | E7: Food | F7: Eat beans, vegetables, eggs, fish and fruit every day. Drink enough clean water.
A8: S004 | B8: S1 | C8: English | D8: 4 | E8: Danger | F8: Go to the clinic at once if you have bleeding, a severe headache or blurred vision. Do not wait.
A9: S005 | B9: S1 | C9: English | D9: 5 | E9: Bleeding | F9: Heavy bleeding in pregnancy or after birth is an emergency. Go to the clinic immediately.
A10: S006 | B10: S1 | C10: English | D10: 6 | E10: Labour | F10: When labour pains start, go to the clinic. Give birth with a trained health worker.
A11: S007 | B11: S1 | C11: English | D11: 7 | E11: Baby | F11: Keep your newborn warm and hold the baby skin to skin. Keep the cord clean and dry.
A12: S008 | B12: S1 | C12: English | D12: 8 | E12: Breastfeeding | F12: Give only breast milk for the first six months. Start breastfeeding within one hour of birth.
A13: S009 | B13: S1 | C13: English | D13: 9 | E13: Vaccine | F13: Vaccines protect your baby from serious diseases. Take your baby for every vaccine on the health card.
A14: S010 | B14: S1 | C14: English | D14: 10 | E14: Contraception | F14: You can choose a family planning method at the clinic. A health worker will help you decide.
A15: S011 | B15: S1 | C15: English | D15: 11 | E15: Malaria | F15: Sleep under a treated mosquito net every night. Go to the clinic if you have a fever.
A16: S012 | B16: S1 | C16: English | D16: 12 | E16: Hygiene | F16: Wash your hands with soap before eating and after using the toilet.
... A44: S040 | B44: S1 | C44: Nyanja | D44: 20 | E44: Fever | F44: Malungo pa nthawi ya mimba angakhale oopsa. Pitani ku kliniki tsiku lomwelo.

Sheet Summary
A1: Summary (formulas, updates from the test sheets)
A3: 1. Keyword-to-topic accuracy by language
A4: Language | B4: Attempts | C4: Correct | D4: Accuracy | E4: Target | F4: Status
A5: English | B5: =COUNTIFS('Keyword Test'!$D$5:$D$84,A5,'Keyword Test'!$J$5:$J$84,"Yes")+COUNTIFS('Keyword Test'!$D$5:$D$84,A5,'Keyword Test'!$J$5:$J$84,"No") -> 40 | C5: =COUNTIFS('Keyword Test'!$D$5:$D$84,A5,'Keyword Test'!$J$5:$J$84,"Yes") -> 36 | D5: =IF(B5=0,"",C5/B5) -> 0.9 | E5: 0.9 | F5: =IF(D5="","",IF(D5>=E5,"Met","Not met")) -> Met
A6: Nyanja | B6: =COUNTIFS('Keyword Test'!$D$5:$D$84,A6,'Keyword Test'!$J$5:$J$84,"Yes")+COUNTIFS('Keyword Test'!$D$5:$D$84,A6,'Keyword Test'!$J$5:$J$84,"No") -> 20 | C6: =COUNTIFS('Keyword Test'!$D$5:$D$84,A6,'Keyword Test'!$J$5:$J$84,"Yes") -> 18 | D6: =IF(B6=0,"",C6/B6) -> 0.9 | E6: 0.8 | F6: =IF(D6="","",IF(D6>=E6,"Met","Not met")) -> Met
A7: Overall | B7: =B5+B6 -> 60 | C7: =C5+C6 -> 54 | D7: =IF(B7=0,"",C7/B7) -> 0.9
A8: Assumption: targets in E5:E6 are placeholders. Replace with the targets in your proposal v2.
A10: 2. Navigation command accuracy
A11: Command | B11: English attempts | C11: English accuracy | D11: Nyanja attempts | E11: Nyanja accuracy
A12: Yes | B12: =COUNTIFS('Command Test'!$C$5:$C$28,"English",'Command Test'!$D$5:$D$28,$A12,'Command Test'!$H$5:$H$28,"Yes")+COUNTIFS('Command Test'!$C$5:$C$28,"English",'Command Test'!$D$5:$D$28,$A12,'Command Test'!$H$5:$H$28,"No") -> 0 | C12: =IF(B12=0,"",COUNTIFS('Command Test'!$C$5:$C$28,"English",'Command Test'!$D$5:$D$28,$A12,'Command Test'!$H$5:$H$28,"Yes")/B12) | D12: =COUNTIFS('Command Test'!$C$5:$C$28,"Nyanja",'Command Test'!$D$5:$D$28,$A12,'Command Test'!$H$5:$H$28,"Yes")+COUNTIFS('Command Test'!$C$5:$C$28,"Nyanja",'Command Test'!$D$5:$D$28,$A12,'Command Test'!$H$5:$H$28,"No") -> 0 | E12: =IF(D12=0,"",COUNTIFS('Command Test'!$C$5:$C$28,"Nyanja",'Command Test'!$D$5:$D$28,$A12,'Command Test'!$H$5:$H$28,"Yes")/D12)
A13: No | B13: =COUNTIFS('Command Test'!$C$5:$C$28,"English",'Command Test'!$D$5:$D$28,$A13,'Command Test'!$H$5:$H$28,"Yes")+COUNTIFS('Command Test'!$C$5:$C$28,"English",'Command Test'!$D$5:$D$28,$A13,'Command Test'!$H$5:$H$28,"No") -> 0 | C13: =IF(B13=0,"",COUNTIFS('Command Test'!$C$5:$C$28,"English",'Command Test'!$D$5:$D$28,$A13,'Command Test'!$H$5:$H$28,"Yes")/B13) | D13: =COUNTIFS('Command Test'!$C$5:$C$28,"Nyanja",'Command Test'!$D$5:$D$28,$A13,'Command Test'!$H$5:$H$28,"Yes")+COUNTIFS('Command Test'!$C$5:$C$28,"Nyanja",'Command Test'!$D$5:$D$28,$A13,'Command Test'!$H$5:$H$28,"No") -> 0 | E13: =IF(D13=0,"",COUNTIFS('Command Test'!$C$5:$C$28,"Nyanja",'Command Test'!$D$5:$D$28,$A13,'Command Test'!$H$5:$H$28,"Yes")/D13)
A14: Repeat | B14: =COUNTIFS('Command Test'!$C$5:$C$28,"English",'Command Test'!$D$5:$D$28,$A14,'Command Test'!$H$5:$H$28,"Yes")+COUNTIFS('Command Test'!$C$5:$C$28,"English",'Command Test'!$D$5:$D$28,$A14,'Command Test'!$H$5:$H$28,"No") -> 0 | C14: =IF(B14=0,"",COUNTIFS('Command Test'!$C$5:$C$28,"English",'Command Test'!$D$5:$D$28,$A14,'Command Test'!$H$5:$H$28,"Yes")/B14) | D14: =COUNTIFS('Command Test'!$C$5:$C$28,"Nyanja",'Command Test'!$D$5:$D$28,$A14,'Command Test'!$H$5:$H$28,"Yes")+COUNTIFS('Command Test'!$C$5:$C$28,"Nyanja",'Command Test'!$D$5:$D$28,$A14,'Command Test'!$H$5:$H$28,"No") -> 0 | E14: =IF(D14=0,"",COUNTIFS('Command Test'!$C$5:$C$28,"Nyanja",'Command Test'!$D$5:$D$28,$A14,'Command Test'!$H$5:$H$28,"Yes")/D14)
A15: Stop | B15: =COUNTIFS('Command Test'!$C$5:$C$28,"English",'Command Test'!$D$5:$D$28,$A15,'Command Test'!$H$5:$H$28,"Yes")+COUNTIFS('Command Test'!$C$5:$C$28,"English",'Command Test'!$D$5:$D$28,$A15,'Command Test'!$H$5:$H$28,"No") -> 0 | C15: =IF(B15=0,"",COUNTIFS('Command Test'!$C$5:$C$28,"English",'Command Test'!$D$5:$D$28,$A15,'Command Test'!$H$5:$H$28,"Yes")/B15) | D15: =COUNTIFS('Command Test'!$C$5:$C$28,"Nyanja",'Command Test'!$D$5:$D$28,$A15,'Command Test'!$H$5:$H$28,"Yes")+COUNTIFS('Command Test'!$C$5:$C$28,"Nyanja",'Command Test'!$D$5:$D$28,$A15,'Command Test'!$H$5:$H$28,"No") -> 0 | E15: =IF(D15=0,"",COUNTIFS('Command Test'!$C$5:$C$28,"Nyanja",'Command Test'!$D$5:$D$28,$A15,'Command Test'!$H$5:$H$28,"Yes")/D15)
A16: Back | B16: =COUNTIFS('Command Test'!$C$5:$C$28,"English",'Command Test'!$D$5:$D$28,$A16,'Command Test'!$H$5:$H$28,"Yes")+COUNTIFS('Command Test'!$C$5:$C$28,"English",'Command Test'!$D$5:$D$28,$A16,'Command Test'!$H$5:$H$28,"No") -> 0 | C16: =IF(B16=0,"",COUNTIFS('Command Test'!$C$5:$C$28,"English",'Command Test'!$D$5:$D$28,$A16,'Command Test'!$H$5:$H$28,"Yes")/B16) | D16: =COUNTIFS('Command Test'!$C$5:$C$28,"Nyanja",'Command Test'!$D$5:$D$28,$A16,'Command Test'!$H$5:$H$28,"Yes")+COUNTIFS('Command Test'!$C$5:$C$28,"Nyanja",'Command Test'!$D$5:$D$28,$A16,'Command Test'!$H$5:$H$28,"No") -> 0 | E16: =IF(D16=0,"",COUNTIFS('Command Test'!$C$5:$C$28,"Nyanja",'Command Test'!$D$5:$D$28,$A16,'Command Test'!$H$5:$H$28,"Yes")/D16)
A17: Menu | B17: =COUNTIFS('Command Test'!$C$5:$C$28,"English",'Command Test'!$D$5:$D$28,$A17,'Command Test'!$H$5:$H$28,"Yes")+COUNTIFS('Command Test'!$C$5:$C$28,"English",'Command Test'!$D$5:$D$28,$A17,'Command Test'!$H$5:$H$28,"No") -> 0 | C17: =IF(B17=0,"",COUNTIFS('Command Test'!$C$5:$C$28,"English",'Command Test'!$D$5:$D$28,$A17,'Command Test'!$H$5:$H$28,"Yes")/B17) | D17: =COUNTIFS('Command Test'!$C$5:$C$28,"Nyanja",'Command Test'!$D$5:$D$28,$A17,'Command Test'!$H$5:$H$28,"Yes")+COUNTIFS('Command Test'!$C$5:$C$28,"Nyanja",'Command Test'!$D$5:$D$28,$A17,'Command Test'!$H$5:$H$28,"No") -> 0 | E17: =IF(D17=0,"",COUNTIFS('Command Test'!$C$5:$C$28,"Nyanja",'Command Test'!$D$5:$D$28,$A17,'Command Test'!$H$5:$H$28,"Yes")/D17)
A18: All commands | B18: =SUM(B12:B17) -> 0 | C18: =IF(B18=0,"",COUNTIFS('Command Test'!$C$5:$C$28,"English",'Command Test'!$H$5:$H$28,"Yes")/B18) | D18: =SUM(D12:D17) -> 0 | E18: =IF(D18=0,"",COUNTIFS('Command Test'!$C$5:$C$28,"Nyanja",'Command Test'!$H$5:$H$28,"Yes")/D18)
A20: 3. Keyword accuracy by topic (find the weak keywords)
A21: Topic | B21: English attempts | C21: English accuracy | D21: Nyanja attempts | E21: Nyanja accuracy
A22: =Keywords!B5 -> Pregnancy | B22: =COUNTIFS('Keyword Test'!$D$5:$D$84,"English",'Keyword Test'!$F$5:$F$84,$A22,'Keyword Test'!$J$5:$J$84,"Yes")+COUNTIFS('Keyword Test'!$D$5:$D$84,"English",'Keyword Test'!$F$5:$F$84,$A22,'Keyword Test'!$J$5:$J$84,"No") -> 2 | C22: =IF(B22=0,"",COUNTIFS('Keyword Test'!$D$5:$D$84,"English",'Keyword Test'!$F$5:$F$84,$A22,'Keyword Test'!$J$5:$J$84,"Yes")/B22) -> 1 | D22: =COUNTIFS('Keyword Test'!$D$5:$D$84,"Nyanja",'Keyword Test'!$F$5:$F$84,$A22,'Keyword Test'!$J$5:$J$84,"Yes")+COUNTIFS('Keyword Test'!$D$5:$D$84,"Nyanja",'Keyword Test'!$F$5:$F$84,$A22,'Keyword Test'!$J$5:$J$84,"No") -> 1 | E22: =IF(D22=0,"",COUNTIFS('Keyword Test'!$D$5:$D$84,"Nyanja",'Keyword Test'!$F$5:$F$84,$A22,'Keyword Test'!$J$5:$J$84,"Yes")/D22) -> 1
A23: =Keywords!B6 -> Clinic | B23: =COUNTIFS('Keyword Test'!$D$5:$D$84,"English",'Keyword Test'!$F$5:$F$84,$A23,'Keyword Test'!$J$5:$J$84,"Yes")+COUNTIFS('Keyword Test'!$D$5:$D$84,"English",'Keyword Test'!$F$5:$F$84,$A23,'Keyword Test'!$J$5:$J$84,"No") -> 2 | C23: =IF(B23=0,"",COUNTIFS('Keyword Test'!$D$5:$D$84,"English",'Keyword Test'!$F$5:$F$84,$A23,'Keyword Test'!$J$5:$J$84,"Yes")/B23) -> 1 | D23: =COUNTIFS('Keyword Test'!$D$5:$D$84,"Nyanja",'Keyword Test'!$F$5:$F$84,$A23,'Keyword Test'!$J$5:$J$84,"Yes")+COUNTIFS('Keyword Test'!$D$5:$D$84,"Nyanja",'Keyword Test'!$F$5:$F$84,$A23,'Keyword Test'!$J$5:$J$84,"No") -> 1 | E23: =IF(D23=0,"",COUNTIFS('Keyword Test'!$D$5:$D$84,"Nyanja",'Keyword Test'!$F$5:$F$84,$A23,'Keyword Test'!$J$5:$J$84,"Yes")/D23) -> 1
A24: =Keywords!B7 -> Food | B24: =COUNTIFS('Keyword Test'!$D$5:$D$84,"English",'Keyword Test'!$F$5:$F$84,$A24,'Keyword Test'!$J$5:$J$84,"Yes")+COUNTIFS('Keyword Test'!$D$5:$D$84,"English",'Keyword Test'!$F$5:$F$84,$A24,'Keyword Test'!$J$5:$J$84,"No") -> 2 | C24: =IF(B24=0,"",COUNTIFS('Keyword Test'!$D$5:$D$84,"English",'Keyword Test'!$F$5:$F$84,$A24,'Keyword Test'!$J$5:$J$84,"Yes")/B24) -> 1 | D24: =COUNTIFS('Keyword Test'!$D$5:$D$84,"Nyanja",'Keyword Test'!$F$5:$F$84,$A24,'Keyword Test'!$J$5:$J$84,"Yes")+COUNTIFS('Keyword Test'!$D$5:$D$84,"Nyanja",'Keyword Test'!$F$5:$F$84,$A24,'Keyword Test'!$J$5:$J$84,"No") -> 1 | E24: =IF(D24=0,"",COUNTIFS('Keyword Test'!$D$5:$D$84,"Nyanja",'Keyword Test'!$F$5:$F$84,$A24,'Keyword Test'!$J$5:$J$84,"Yes")/D24) -> 1
A25: =Keywords!B8 -> Danger | B25: =COUNTIFS('Keyword Test'!$D$5:$D$84,"English",'Keyword Test'!$F$5:$F$84,$A25,'Keyword Test'!$J$5:$J$84,"Yes")+COUNTIFS('Keyword Test'!$D$5:$D$84,"English",'Keyword Test'!$F$5:$F$84,$A25,'Keyword Test'!$J$5:$J$84,"No") -> 2 | C25: =IF(B25=0,"",COUNTIFS('Keyword Test'!$D$5:$D$84,"English",'Keyword Test'!$F$5:$F$84,$A25,'Keyword Test'!$J$5:$J$84,"Yes")/B25) -> 1 | D25: =COUNTIFS('Keyword Test'!$D$5:$D$84,"Nyanja",'Keyword Test'!$F$5:$F$84,$A25,'Keyword Test'!$J$5:$J$84,"Yes")+COUNTIFS('Keyword Test'!$D$5:$D$84,"Nyanja",'Keyword Test'!$F$5:$F$84,$A25,'Keyword Test'!$J$5:$J$84,"No") -> 1 | E25: =IF(D25=0,"",COUNTIFS('Keyword Test'!$D$5:$D$84,"Nyanja",'Keyword Test'!$F$5:$F$84,$A25,'Keyword Test'!$J$5:$J$84,"Yes")/D25) -> 1
A26: =Keywords!B9 -> Bleeding | B26: =COUNTIFS('Keyword Test'!$D$5:$D$84,"English",'Keyword Test'!$F$5:$F$84,$A26,'Keyword Test'!$J$5:$J$84,"Yes")+COUNTIFS('Keyword Test'!$D$5:$D$84,"English",'Keyword Test'!$F$5:$F$84,$A26,'Keyword Test'!$J$5:$J$84,"No") -> 2 | C26: =IF(B26=0,"",COUNTIFS('Keyword Test'!$D$5:$D$84,"English",'Keyword Test'!$F$5:$F$84,$A26,'Keyword Test'!$J$5:$J$84,"Yes")/B26) -> 1 | D26: =COUNTIFS('Keyword Test'!$D$5:$D$84,"Nyanja",'Keyword Test'!$F$5:$F$84,$A26,'Keyword Test'!$J$5:$J$84,"Yes")+COUNTIFS('Keyword Test'!$D$5:$D$84,"Nyanja",'Keyword Test'!$F$5:$F$84,$A26,'Keyword Test'!$J$5:$J$84,"No") -> 1 | E26: =IF(D26=0,"",COUNTIFS('Keyword Test'!$D$5:$D$84,"Nyanja",'Keyword Test'!$F$5:$F$84,$A26,'Keyword Test'!$J$5:$J$84,"Yes")/D26) -> 1
A27: =Keywords!B10 -> Labour | B27: =COUNTIFS('Keyword Test'!$D$5:$D$84,"English",'Keyword Test'!$F$5:$F$84,$A27,'Keyword Test'!$J$5:$J$84,"Yes")+COUNTIFS('Keyword Test'!$D$5:$D$84,"English",'Keyword Test'!$F$5:$F$84,$A27,'Keyword Test'!$J$5:$J$84,"No") -> 2 | C27: =IF(B27=0,"",COUNTIFS('Keyword Test'!$D$5:$D$84,"English",'Keyword Test'!$F$5:$F$84,$A27,'Keyword Test'!$J$5:$J$84,"Yes")/B27) -> 0 | D27: =COUNTIFS('Keyword Test'!$D$5:$D$84,"Nyanja",'Keyword Test'!$F$5:$F$84,$A27,'Keyword Test'!$J$5:$J$84,"Yes")+COUNTIFS('Keyword Test'!$D$5:$D$84,"Nyanja",'Keyword Test'!$F$5:$F$84,$A27,'Keyword Test'!$J$5:$J$84,"No") -> 1 | E27: =IF(D27=0,"",COUNTIFS('Keyword Test'!$D$5:$D$84,"Nyanja",'Keyword Test'!$F$5:$F$84,$A27,'Keyword Test'!$J$5:$J$84,"Yes")/D27) -> 1
A28: =Keywords!B11 -> Baby | B28: =COUNTIFS('Keyword Test'!$D$5:$D$84,"English",'Keyword Test'!$F$5:$F$84,$A28,'Keyword Test'!$J$5:$J$84,"Yes")+COUNTIFS('Keyword Test'!$D$5:$D$84,"English",'Keyword Test'!$F$5:$F$84,$A28,'Keyword Test'!$J$5:$J$84,"No") -> 2 | C28: =IF(B28=0,"",COUNTIFS('Keyword Test'!$D$5:$D$84,"English",'Keyword Test'!$F$5:$F$84,$A28,'Keyword Test'!$J$5:$J$84,"Yes")/B28) -> 1 | D28: =COUNTIFS('Keyword Test'!$D$5:$D$84,"Nyanja",'Keyword Test'!$F$5:$F$84,$A28,'Keyword Test'!$J$5:$J$84,"Yes")+COUNTIFS('Keyword Test'!$D$5:$D$84,"Nyanja",'Keyword Test'!$F$5:$F$84,$A28,'Keyword Test'!$J$5:$J$84,"No") -> 1 | E28: =IF(D28=0,"",COUNTIFS('Keyword Test'!$D$5:$D$84,"Nyanja",'Keyword Test'!$F$5:$F$84,$A28,'Keyword Test'!$J$5:$J$84,"Yes")/D28) -> 0
A29: =Keywords!B12 -> Breastfeeding | B29: =COUNTIFS('Keyword Test'!$D$5:$D$84,"English",'Keyword Test'!$F$5:$F$84,$A29,'Keyword Test'!$J$5:$J$84,"Yes")+COUNTIFS('Keyword Test'!$D$5:$D$84,"English",'Keyword Test'!$F$5:$F$84,$A29,'Keyword Test'!$J$5:$J$84,"No") -> 2 | C29: =IF(B29=0,"",COUNTIFS('Keyword Test'!$D$5:$D$84,"English",'Keyword Test'!$F$5:$F$84,$A29,'Keyword Test'!$J$5:$J$84,"Yes")/B29) -> 1 | D29: =COUNTIFS('Keyword Test'!$D$5:$D$84,"Nyanja",'Keyword Test'!$F$5:$F$84,$A29,'Keyword Test'!$J$5:$J$84,"Yes")+COUNTIFS('Keyword Test'!$D$5:$D$84,"Nyanja",'Keyword Test'!$F$5:$F$84,$A29,'Keyword Test'!$J$5:$J$84,"No") -> 1 | E29: =IF(D29=0,"",COUNTIFS('Keyword Test'!$D$5:$D$84,"Nyanja",'Keyword Test'!$F$5:$F$84,$A29,'Keyword Test'!$J$5:$J$84,"Yes")/D29) -> 1
A30: =Keywords!B13 -> Vaccine | B30: =COUNTIFS('Keyword Test'!$D$5:$D$84,"English",'Keyword Test'!$F$5:$F$84,$A30,'Keyword Test'!$J$5:$J$84,"Yes")+COUNTIFS('Keyword Test'!$D$5:$D$84,"English",'Keyword Test'!$F$5:$F$84,$A30,'Keyword Test'!$J$5:$J$84,"No") -> 2 | C30: =IF(B30=0,"",COUNTIFS('Keyword Test'!$D$5:$D$84,"English",'Keyword Test'!$F$5:$F$84,$A30,'Keyword Test'!$J$5:$J$84,"Yes")/B30) -> 1 | D30: =COUNTIFS('Keyword Test'!$D$5:$D$84,"Nyanja",'Keyword Test'!$F$5:$F$84,$A30,'Keyword Test'!$J$5:$J$84,"Yes")+COUNTIFS('Keyword Test'!$D$5:$D$84,"Nyanja",'Keyword Test'!$F$5:$F$84,$A30,'Keyword Test'!$J$5:$J$84,"No") -> 1 | E30: =IF(D30=0,"",COUNTIFS('Keyword Test'!$D$5:$D$84,"Nyanja",'Keyword Test'!$F$5:$F$84,$A30,'Keyword Test'!$J$5:$J$84,"Yes")/D30) -> 1
A31: =Keywords!B14 -> Contraception | B31: =COUNTIFS('Keyword Test'!$D$5:$D$84,"English",'Keyword Test'!$F$5:$F$84,$A31,'Keyword Test'!$J$5:$J$84,"Yes")+COUNTIFS('Keyword Test'!$D$5:$D$84,"English",'Keyword Test'!$F$5:$F$84,$A31,'Keyword Test'!$J$5:$J$84,"No") -> 2 | C31: =IF(B31=0,"",COUNTIFS('Keyword Test'!$D$5:$D$84,"English",'Keyword Test'!$F$5:$F$84,$A31,'Keyword Test'!$J$5:$J$84,"Yes")/B31) -> 1 | D31: =COUNTIFS('Keyword Test'!$D$5:$D$84,"Nyanja",'Keyword Test'!$F$5:$F$84,$A31,'Keyword Test'!$J$5:$J$84,"Yes")+COUNTIFS('Keyword Test'!$D$5:$D$84,"Nyanja",'Keyword Test'!$F$5:$F$84,$A31,'Keyword Test'!$J$5:$J$84,"No") -> 1 | E31: =IF(D31=0,"",COUNTIFS('Keyword Test'!$D$5:$D$84,"Nyanja",'Keyword Test'!$F$5:$F$84,$A31,'Keyword Test'!$J$5:$J$84,"Yes")/D31) -> 1
A32: =Keywords!B15 -> Malaria | B32: =COUNTIFS('Keyword Test'!$D$5:$D$84,"English",'Keyword Test'!$F$5:$F$84,$A32,'Keyword Test'!$J$5:$J$84,"Yes")+COUNTIFS('Keyword Test'!$D$5:$D$84,"English",'Keyword Test'!$F$5:$F$84,$A32,'Keyword Test'!$J$5:$J$84,"No") -> 2 | C32: =IF(B32=0,"",COUNTIFS('Keyword Test'!$D$5:$D$84,"English",'Keyword Test'!$F$5:$F$84,$A32,'Keyword Test'!$J$5:$J$84,"Yes")/B32) -> 1 | D32: =COUNTIFS('Keyword Test'!$D$5:$D$84,"Nyanja",'Keyword Test'!$F$5:$F$84,$A32,'Keyword Test'!$J$5:$J$84,"Yes")+COUNTIFS('Keyword Test'!$D$5:$D$84,"Nyanja",'Keyword Test'!$F$5:$F$84,$A32,'Keyword Test'!$J$5:$J$84,"No") -> 1 | E32: =IF(D32=0,"",COUNTIFS('Keyword Test'!$D$5:$D$84,"Nyanja",'Keyword Test'!$F$5:$F$84,$A32,'Keyword Test'!$J$5:$J$84,"Yes")/D32) -> 1
A33: =Keywords!B16 -> Hygiene | B33: =COUNTIFS('Keyword Test'!$D$5:$D$84,"English",'Keyword Test'!$F$5:$F$84,$A33,'Keyword Test'!$J$5:$J$84,"Yes")+COUNTIFS('Keyword Test'!$D$5:$D$84,"English",'Keyword Test'!$F$5:$F$84,$A33,'Keyword Test'!$J$5:$J$84,"No") -> 2 | C33: =IF(B33=0,"",COUNTIFS('Keyword Test'!$D$5:$D$84,"English",'Keyword Test'!$F$5:$F$84,$A33,'Keyword Test'!$J$5:$J$84,"Yes")/B33) -> 1 | D33: =COUNTIFS('Keyword Test'!$D$5:$D$84,"Nyanja",'Keyword Test'!$F$5:$F$84,$A33,'Keyword Test'!$J$5:$J$84,"Yes")+COUNTIFS('Keyword Test'!$D$5:$D$84,"Nyanja",'Keyword Test'!$F$5:$F$84,$A33,'Keyword Test'!$J$5:$J$84,"No") -> 1 | E33: =IF(D33=0,"",COUNTIFS('Keyword Test'!$D$5:$D$84,"Nyanja",'Keyword Test'!$F$5:$F$84,$A33,'Keyword Test'!$J$5:$J$84,"Yes")/D33) -> 0
... A41: =Keywords!B24 -> Fever | B41: =COUNTIFS('Keyword Test'!$D$5:$D$84,"English",'Keyword Test'!$F$5:$F$84,$A41,'Keyword Test'!$J$5:$J$84,"Yes")+COUNTIFS('Keyword Test'!$D$5:$D$84,"English",'Keyword Test'!$F$5:$F$84,$A41,'Keyword Test'!$J$5:$J$84,"No") -> 2 | C41: =IF(B41=0,"",COUNTIFS('Keyword Test'!$D$5:$D$84,"English",'Keyword Test'!$F$5:$F$84,$A41,'Keyword Test'!$J$5:$J$84,"Yes")/B41) -> 0.5 | D41: =COUNTIFS('Keyword Test'!$D$5:$D$84,"Nyanja",'Keyword Test'!$F$5:$F$84,$A41,'Keyword Test'!$J$5:$J$84,"Yes")+COUNTIFS('Keyword Test'!$D$5:$D$84,"Nyanja",'Keyword Test'!$F$5:$F$84,$A41,'Keyword Test'!$J$5:$J$84,"No") -> 1 | E41: =IF(D41=0,"",COUNTIFS('Keyword Test'!$D$5:$D$84,"Nyanja",'Keyword Test'!$F$5:$F$84,$A41,'Keyword Test'!$J$5:$J$84,"Yes")/D41) -> 1
A43: 4. Task success and response time (Keyword Test)
A44: Language | B44: Scored trials | C44: Correct audio played | D44: Task success | E44: Avg response time (s) | F44: Max response time (s)
A45: English | B45: =COUNTIFS('Keyword Test'!$D$5:$D$84,A45,'Keyword Test'!$M$5:$M$84,"Yes")+COUNTIFS('Keyword Test'!$D$5:$D$84,A45,'Keyword Test'!$M$5:$M$84,"No") -> 3 | C45: =COUNTIFS('Keyword Test'!$D$5:$D$84,A45,'Keyword Test'!$M$5:$M$84,"Yes") -> 1 | D45: =IF(B45=0,"",C45/B45) -> 0.33333333 | E45: =IFERROR(AVERAGEIFS('Keyword Test'!$L$5:$L$84,'Keyword Test'!$D$5:$D$84,A45),"") -> 5.079 | F45: =IF(COUNTIFS('Keyword Test'!$D$5:$D$84,A45,'Keyword Test'!$L$5:$L$84,">0")=0,"",_xlfn.MAXIFS('Keyword Test'!$L$5:$L$84,'Keyword Test'!$D$5:$D$84,A45)) -> #NAME?
A46: Nyanja | B46: =COUNTIFS('Keyword Test'!$D$5:$D$84,A46,'Keyword Test'!$M$5:$M$84,"Yes")+COUNTIFS('Keyword Test'!$D$5:$D$84,A46,'Keyword Test'!$M$5:$M$84,"No") -> 0 | C46: =COUNTIFS('Keyword Test'!$D$5:$D$84,A46,'Keyword Test'!$M$5:$M$84,"Yes") -> 0 | D46: =IF(B46=0,"",C46/B46) | E46: =IFERROR(AVERAGEIFS('Keyword Test'!$L$5:$L$84,'Keyword Test'!$D$5:$D$84,A46),"") -> 6.43 | F46: =IF(COUNTIFS('Keyword Test'!$D$5:$D$84,A46,'Keyword Test'!$L$5:$L$84,">0")=0,"",_xlfn.MAXIFS('Keyword Test'!$L$5:$L$84,'Keyword Test'!$D$5:$D$84,A46)) -> #NAME?
A47: Overall | B47: =B45+B46 -> 3 | C47: =C45+C46 -> 1 | D47: =IF(B47=0,"",C47/B47) -> 0.33333333 | E47: =IF(COUNT('Keyword Test'!$L$5:$L$84)=0,"",AVERAGE('Keyword Test'!$L$5:$L$84)) -> 5.5293333 | F47: =IF(COUNT('Keyword Test'!$L$5:$L$84)=0,"",MAX('Keyword Test'!$L$5:$L$84)) -> 31
A49: 5. Keyword accuracy by condition
A50: Condition | B50: English attempts | C50: English accuracy | D50: Nyanja attempts | E50: Nyanja accuracy
A51: Quiet | B51: =COUNTIFS('Keyword Test'!$D$5:$D$84,"English",'Keyword Test'!$C$5:$C$84,$A51,'Keyword Test'!$J$5:$J$84,"Yes")+COUNTIFS('Keyword Test'!$D$5:$D$84,"English",'Keyword Test'!$C$5:$C$84,$A51,'Keyword Test'!$J$5:$J$84,"No") -> 40 | C51: =IF(B51=0,"",COUNTIFS('Keyword Test'!$D$5:$D$84,"English",'Keyword Test'!$C$5:$C$84,$A51,'Keyword Test'!$J$5:$J$84,"Yes")/B51) -> 0.9 | D51: =COUNTIFS('Keyword Test'!$D$5:$D$84,"Nyanja",'Keyword Test'!$C$5:$C$84,$A51,'Keyword Test'!$J$5:$J$84,"Yes")+COUNTIFS('Keyword Test'!$D$5:$D$84,"Nyanja",'Keyword Test'!$C$5:$C$84,$A51,'Keyword Test'!$J$5:$J$84,"No") -> 20 | E51: =IF(D51=0,"",COUNTIFS('Keyword Test'!$D$5:$D$84,"Nyanja",'Keyword Test'!$C$5:$C$84,$A51,'Keyword Test'!$J$5:$J$84,"Yes")/D51) -> 0.9
A52: Noisy | B52: =COUNTIFS('Keyword Test'!$D$5:$D$84,"English",'Keyword Test'!$C$5:$C$84,$A52,'Keyword Test'!$J$5:$J$84,"Yes")+COUNTIFS('Keyword Test'!$D$5:$D$84,"English",'Keyword Test'!$C$5:$C$84,$A52,'Keyword Test'!$J$5:$J$84,"No") -> 0 | C52: =IF(B52=0,"",COUNTIFS('Keyword Test'!$D$5:$D$84,"English",'Keyword Test'!$C$5:$C$84,$A52,'Keyword Test'!$J$5:$J$84,"Yes")/B52) | D52: =COUNTIFS('Keyword Test'!$D$5:$D$84,"Nyanja",'Keyword Test'!$C$5:$C$84,$A52,'Keyword Test'!$J$5:$J$84,"Yes")+COUNTIFS('Keyword Test'!$D$5:$D$84,"Nyanja",'Keyword Test'!$C$5:$C$84,$A52,'Keyword Test'!$J$5:$J$84,"No") -> 0 | E52: =IF(D52=0,"",COUNTIFS('Keyword Test'!$D$5:$D$84,"Nyanja",'Keyword Test'!$C$5:$C$84,$A52,'Keyword Test'!$J$5:$J$84,"Yes")/D52)
...
